<?xml version="1.0" encoding="UTF-8"?>
<sdf version="1.6">
  <model name="zero_turn_mower">
    <static>false</static>
    <link name="base_link">
      <pose>0 0 0 0 0 0</pose>
      <inertial>
        <pose>0 0 0 0 0 0</pose>
        <mass>220.0</mass>
        <inertia>
          <ixx>40</ixx>
          <ixy>0.0</ixy>
          <iyy>150</iyy>
          <ixz>0.0</ixz>
          <iyz>0.0</iyz>
          <izz>150</izz>
        </inertia>
      </inertial>
      <collision name="base_collision">
        <pose>0 0 0.2 0 0 0</pose>
        <geometry>
          <box>
            <size>1.8 0.65 0.55</size>
          </box>
        </geometry>
        <surface>
          <contact>
            <ode/>
          </contact>
          <friction>
            <ode/>
          </friction>
        </surface>
      </collision>
      <visual name="base_visual_base">
        <pose>0 0 0 0 0 0</pose>
        <geometry>
          <box>
            <size>1.81 0.66 0.1</size>
          </box>
        </geometry>
        <material>
          <ambient>0.9 0.36 0 1</ambient>
          <diffuse>0.9 0.36 0 1</diffuse>
          <specular>0 0 0 0</specular>
          <emissive>0 0 0 1</emissive>
        </material>
      </visual>
      <visual name="base_visual">
        <pose>-0.5 0 0.2 0 0 0</pose>
        <geometry>
          <box>
            <size>0.8 0.65 0.55</size>
          </box>
        </geometry>
        <material>
          <ambient>1.0 0.4 0 1</ambient>
          <diffuse>1.0 0.4 0 1</diffuse>
          <specular>0 0 0 0</specular>
          <emissive>0.2 0.08 0 1</emissive>
        </material>
      </visual>
      <!-- Cutter board -->
      <visual name="base_visual_cutter_r">
        <pose>0.2 -0.5 -0.1 0 0 0</pose>
        <geometry>
          <cylinder>
            <radius>0.25</radius>
            <length>0.1</length>
          </cylinder>
        </geometry>
        <material>
          <ambient>1.0 0.4 0 1</ambient>
          <diffuse>1.0 0.4 0 1</diffuse>
          <specular>0 0 0 0</specular>
          <emissive>0.2 0.08 0 1</emissive>
        </material>
      </visual>
      <visual name="base_visual_cutter_c">
        <pose>0.23 0 -0.1 0 0 0</pose>
        <geometry>
          <cylinder>
            <radius>0.25</radius>
            <length>0.1</length>
          </cylinder>
        </geometry>
        <material>
          <ambient>1.0 0.4 0 1</ambient>
          <diffuse>1.0 0.4 0 1</diffuse>
          <specular>0 0 0 0</specular>
          <emissive>0.2 0.08 0 1</emissive>
        </material>
      </visual>
      <visual name="base_visual_cutter_l">
        <pose>0.2 0.5 -0.1 0 0 0</pose>
        <geometry>
          <cylinder>
            <radius>0.25</radius>
            <length>0.1</length>
          </cylinder>
        </geometry>
        <material>
          <ambient>1.0 0.4 0 1</ambient>
          <diffuse>1.0 0.4 0 1</diffuse>
          <specular>0 0 0 0</specular>
          <emissive>0.2 0.08 0 1</emissive>
        </material>
      </visual>
      <!-- Casters -->
      <collision name="left_caster_collision">
        <pose>0.85 0.38 -0.1 0 0 0</pose>
        <geometry>
          <sphere>
            <radius>.1</radius>
          </sphere>
        </geometry>
        <surface>
          <friction>
            <ode>
              <mu>0</mu>
              <mu2>0</mu2>
              <slip1>1.0</slip1>
              <slip2>1.0</slip2>
            </ode>
          </friction>
        </surface>
      </collision>
      <visual name="left_caster_visual_base">
        <pose>0.85 0.38 -0.01 0 0 0</pose>
        <geometry>
          <cylinder>
            <radius>0.1</radius>
            <length>0.1</length>
          </cylinder>
        </geometry>
        <material>
          <ambient>0.9 0.36 0 1</ambient>
          <diffuse>0.9 0.36 0 1</diffuse>
          <specular>0 0 0 0</specular>
          <emissive>0 0 0 1</emissive>
        </material>
      </visual>
      <visual name="left_caster_visual">
        <pose>0.85 0.38 -0.1 0 0 0</pose>
        <geometry>
          <sphere>
            <radius>.1</radius>
          </sphere>
        </geometry>
        <material>
          <ambient>1.0 0.2 0.2 1</ambient>
          <diffuse>1.0 0.1 0.1 1</diffuse>
          <specular>0 0 0 0</specular>
          <emissive>0 0 0 1</emissive>
        </material>
      </visual>
      <collision name="right_caster_collision">
        <pose>0.85 -0.38 -0.1 0 0 0</pose>
        <geometry>
          <sphere>
            <radius>.1</radius>
          </sphere>
        </geometry>
        <surface>
          <friction>
            <ode>
              <mu>0</mu>
              <mu2>0</mu2>
              <slip1>1.0</slip1>
              <slip2>1.0</slip2>
            </ode>
          </friction>
        </surface>
      </collision>
      <visual name="right_caster_visual_base">
        <pose>0.85 -0.38 -0.01 0 0 0</pose>
        <geometry>
          <cylinder>
            <radius>0.1</radius>
            <length>0.1</length>
          </cylinder>
        </geometry>
        <material>
          <ambient>0.9 0.36 0 1</ambient>
          <diffuse>0.9 0.36 0 1</diffuse>
          <specular>0 0 0 0</specular>
          <emissive>0 0 0 1</emissive>
        </material>
      </visual>
      <visual name="right_caster_visual">
        <pose>0.85 -0.38 -0.1 0 0 0</pose>
        <geometry>
          <sphere>
            <radius>.1</radius>
          </sphere>
        </geometry>
        <material>
          <ambient>0.2 1.0 0.2 1</ambient>
          <diffuse>0.1 1.0 0.1 1</diffuse>
          <specular>0 0 0 0</specular>
          <emissive>0 0 0 1</emissive>
        </material>
      </visual>
    </link>
    <!-- Wheels -->
    <link name="left_wheel_link">
      <pose>-0.45 0.45 0.0215 0 1.57079632679 1.57079632679</pose>
      <inertial>
        <mass>8.0</mass>
        <!-- estimated from http://www.rzrforums.net/wheels-tires/1729-tire-wheel-weights-most-sizes.html -->
        <inertia>
          <ixx>0.5</ixx>
          <ixy>0.0</ixy>
          <iyy>0.5</iyy>
          <ixz>0.0</ixz>
          <iyz>0.0</iyz>
          <izz>1.0</izz>
        </inertia>
      </inertial>
      <collision name="left_wheel_link_collision">
        <geometry>
          <cylinder>
            <radius>0.22</radius>
            <length>0.22</length>
          </cylinder>
        </geometry>
        <max_contacts>1</max_contacts>
        <surface>
          <friction>
            <ode>
              <mu>0.4</mu>
              <mu2>0.6</mu2>
            </ode>
          </friction>
          <bounce/>
          <contact>
            <ode>
              <min_depth>0.005</min_depth>
              <kp>1e8</kp>
            </ode>
          </contact>
        </surface>
      </collision>
      <visual name="left_wheel_link_visual">
        <pose>0 0 0 1.57079632679 0 0</pose>
        <geometry>
          <mesh>
            <scale>2.8 2.0 2.8</scale>
            <uri>model://r1_rover/meshes/wheel_link.STL</uri>
          </mesh>
        </geometry>
        <material>
          <script>
            <name>Gazebo/FlatBlack</name>
            <uri>file://media/materials/scripts/gazebo.material</uri>
          </script>
        </material>
      </visual>
      <visual name="left_wheel_marker_visual">
        <pose>0.17 0 0 0 0 0</pose>
        <geometry>
          <box>
            <size>.10 .01 .21</size>
          </box>
        </geometry>
        <material>
          <ambient>1.0 0.2 0.2 1</ambient>
          <diffuse>1.0 0.1 0.1 1</diffuse>
          <specular>0 0 0 0</specular>
          <emissive>0 0 0 1</emissive>
        </material>
      </visual>
    </link>
    <joint name="left_wheel_joint" type="revolute">
      <child>left_wheel_link</child>
      <parent>base_link</parent>
      <axis>
        <xyz>0 1 0</xyz>
        <use_parent_model_frame>1</use_parent_model_frame>
      </axis>
    </joint>
    <link name="right_wheel_link">
      <pose>-0.45 -0.45 0.0215 0 1.57079632679 1.57079632679</pose>
      <inertial>
        <mass>8.0</mass>
        <!-- estimated from http://www.rzrforums.net/wheels-tires/1729-tire-wheel-weights-most-sizes.html -->
        <inertia>
          <ixx>0.5</ixx>
          <ixy>0.0</ixy>
          <iyy>0.5</iyy>
          <ixz>0.0</ixz>
          <iyz>0.0</iyz>
          <izz>1.0</izz>
        </inertia>
      </inertial>
      <collision name="right_wheel_link_collision">
        <geometry>
          <cylinder>
            <radius>0.22</radius>
            <length>0.22</length>
          </cylinder>
        </geometry>
        <max_contacts>1</max_contacts>
        <surface>
          <friction>
            <ode>
              <mu>0.4</mu>
              <mu2>0.6</mu2>
            </ode>
          </friction>
          <bounce/>
          <contact>
            <ode>
              <min_depth>0.005</min_depth>
              <kp>1e8</kp>
            </ode>
          </contact>
        </surface>
      </collision>
      <visual name="right_wheel_link_visual">
        <pose>0 0 0 1.57079632679 0 0</pose>
        <geometry>
          <mesh>
            <scale>2.8 2.0 2.8</scale>
            <uri>model://r1_rover/meshes/wheel_link.STL</uri>
          </mesh>
        </geometry>
        <material>
          <script>
            <name>Gazebo/FlatBlack</name>
            <uri>file://media/materials/scripts/gazebo.material</uri>
          </script>
        </material>
      </visual>
      <visual name="right_wheel_marker_visual">
        <pose>0.17 0 0 0 0 0</pose>
        <geometry>
          <box>
            <size>.10 .01 .21</size>
          </box>
        </geometry>
        <material>
          <ambient>0.2 1.0 0.2 1</ambient>
          <diffuse>0.1 1.0 0.1 1</diffuse>
          <specular>0 0 0 0</specular>
          <emissive>0 0 0 1</emissive>
        </material>
      </visual>
    </link>
    <joint name="right_wheel_joint" type="revolute">
      <child>right_wheel_link</child>
      <parent>base_link</parent>
      <axis>
        <xyz>0 1 0</xyz>
        <use_parent_model_frame>1</use_parent_model_frame>
      </axis>
    </joint>
    <link name="engine_visual_link">
      <pose>-0.9 0 0.5 0 0 0</pose>
      <visual name="engine_visual_link_visual">
        <pose>0 0 0 1.57079632679 0 0</pose>
        <geometry>
          <cylinder>
            <radius>0.1</radius>
            <length>0.08</length>
          </cylinder>
        </geometry>
        <material>
          <ambient>0.3 0.3 0.2 1</ambient>
          <diffuse>1.0 1.0 0.1 1</diffuse>
          <specular>0 0 0 0</specular>
          <emissive>0 0 0 1</emissive>
        </material>
      </visual>
    </link>
    <joint name="engine_visual_joint" type="revolute">
      <child>engine_visual_link</child>
      <parent>base_link</parent>
      <axis>
        <xyz>1 0 0</xyz>
        <use_parent_model_frame>1</use_parent_model_frame>
      </axis>
    </joint>
    <link name="cutter_blades_link">
      <pose>0.2 0 -0.1 0 0 0</pose>
      <visual name="cutter_blades_marker_visual">
        <pose>0.8 0 0 0 0 0</pose>
        <geometry>
          <box>
            <size>.20 .01 .15</size>
          </box>
        </geometry>
        <material>
          <ambient>1.0 0 0 1</ambient>
          <diffuse>1.0 0 0 1</diffuse>
          <specular>0 0 0 0</specular>
          <emissive>0 0 0 1</emissive>
        </material>
      </visual>
    </link>
    <joint name="cutter_blades_joint" type="revolute">
      <child>cutter_blades_link</child>
      <parent>base_link</parent>
      <axis>
        <xyz>0 0 1</xyz>
        <use_parent_model_frame>1</use_parent_model_frame>
      </axis>
    </joint>
    <link name="alarm_visual_link">
      <pose>-0.45 0 0.65 0 0 0</pose>
      <visual name="alarm_visual_sphere_visual">
        <pose>0 0 0 1.57079632679 0 0</pose>
        <geometry>
          <sphere>
            <radius>0.07</radius>
          </sphere>
        </geometry>
        <material>
          <ambient>0.7 0.7 0.0 1</ambient>
          <diffuse>0.7 0.7 0.0 1</diffuse>
          <specular>0 0 0 0</specular>
          <emissive>0 0 0 1</emissive>
        </material>
      </visual>
      <visual name="alarm_visual_belt_visual">
        <pose>0 0 0 1.57079632679 0 0</pose>
        <geometry>
          <cylinder>
            <radius>0.08</radius>
            <length>0.02</length>
          </cylinder>
        </geometry>
        <material>
          <ambient>1.0 0 0 1</ambient>
          <diffuse>1.0 0 0 1</diffuse>
          <specular>0 0 0 0</specular>
          <emissive>0 0 0 1</emissive>
        </material>
      </visual>
      <visual name="alarm_visual_support_visual">
        <pose>0 0 -0.1 0 0 0</pose>
        <geometry>
          <box>
            <size>.05 .05 .2</size>
          </box>
        </geometry>
        <material>
          <ambient>0.7 0.7 0.0 1</ambient>
          <diffuse>0.7 0.7 0.0 1</diffuse>
          <specular>0 0 0 0</specular>
          <emissive>0 0 0 1</emissive>
        </material>
      </visual>
    </link>
    <joint name="alarm_visual_joint" type="revolute">
      <child>alarm_visual_link</child>
      <parent>base_link</parent>
      <axis>
        <xyz>0 0 1</xyz>
        <use_parent_model_frame>1</use_parent_model_frame>
      </axis>
    </joint>
    <link name="rover/imu_link">
      <pose>-0.45 0 0.4 0 0 0</pose>
      <inertial>
        <pose>0 0 0 0 0 0</pose>
        <mass>0.015</mass>
        <inertia>
          <ixx>1e-05</ixx>
          <ixy>0</ixy>
          <ixz>0</ixz>
          <iyy>1e-05</iyy>
          <iyz>0</iyz>
          <izz>1e-05</izz>
        </inertia>
      </inertial>
      <!--<visual name='imu_box'>
        <pose>0 0 0 0 0 0</pose>
        <geometry>
          <box>
            <size>.05 .05 .02</size>
          </box>
        </geometry>
        <material>
          <emissive>1.0 0.0 0.0 1</emissive>
        </material>
      </visual>-->
      <!--uncomment visual block to see IMU-->
    </link>
    <joint name="rover/imu_joint" type="revolute">
      <child>rover/imu_link</child>
      <parent>base_link</parent>
      <axis>
        <xyz>1 0 0</xyz>
        <limit>
          <lower>0</lower>
          <upper>0</upper>
          <effort>0</effort>
          <velocity>0</velocity>
        </limit>
        <dynamics>
          <spring_reference>0</spring_reference>
          <spring_stiffness>0</spring_stiffness>
        </dynamics>
        <use_parent_model_frame>1</use_parent_model_frame>
      </axis>
    </joint>
    <include>
      <uri>model://gps</uri>
      <pose>-0.45 0 0.4 0 0 0</pose>
      <name>gps</name>
    </include>
    <joint name="gps_joint" type="fixed">
      <child>gps::link</child>
      <parent>base_link</parent>
    </joint>
    <plugin name="gazebo_imu_plugin" filename="libgazebo_imu_plugin.so">
      <robotNamespace/>
      <linkName>rover/imu_link</linkName>
      <imuTopic>/imu</imuTopic>
      <gyroscopeNoiseDensity>0.0003394</gyroscopeNoiseDensity>
      <gyroscopeRandomWalk>3.8785e-05</gyroscopeRandomWalk>
      <gyroscopeBiasCorrelationTime>1000.0</gyroscopeBiasCorrelationTime>
      <gyroscopeTurnOnBiasSigma>0.0087</gyroscopeTurnOnBiasSigma>
      <accelerometerNoiseDensity>0.004</accelerometerNoiseDensity>
      <accelerometerRandomWalk>0.006</accelerometerRandomWalk>
      <accelerometerBiasCorrelationTime>300.0</accelerometerBiasCorrelationTime>
      <accelerometerTurnOnBiasSigma>0.196</accelerometerTurnOnBiasSigma>
    </plugin>
    <plugin name="groundtruth_plugin" filename="libgazebo_groundtruth_plugin.so">
      <robotNamespace/>
    </plugin>
    <plugin name="magnetometer_plugin" filename="libgazebo_magnetometer_plugin.so">
      <robotNamespace/>
      <pubRate>20</pubRate>
      <noiseDensity>0.0004</noiseDensity>
      <randomWalk>6.4e-06</randomWalk>
      <biasCorrelationTime>600</biasCorrelationTime>
      <magTopic>/mag</magTopic>
    </plugin>
    <plugin name="barometer_plugin" filename="libgazebo_barometer_plugin.so">
      <robotNamespace/>
      <pubRate>10</pubRate>
      <baroTopic>/baro</baroTopic>
    </plugin>
    <plugin name="mavlink_interface" filename="libgazebo_mavlink_interface.so">
      <robotNamespace/>
      <imuSubTopic>/imu</imuSubTopic>
      <magSubTopic>/mag</magSubTopic>
      <baroSubTopic>/baro</baroSubTopic>
      <mavlink_addr>INADDR_ANY</mavlink_addr>
      <mavlink_tcp_port>{{ mavlink_tcp_port }}</mavlink_tcp_port>
      <mavlink_udp_port>{{ mavlink_udp_port }}</mavlink_udp_port>
      <serialEnabled>{{ serial_enabled }}</serialEnabled>
      <serialDevice>{{ serial_device }}</serialDevice>
      <baudRate>{{ serial_baudrate }}</baudRate>
      <qgc_addr>INADDR_ANY</qgc_addr>
      <qgc_udp_port>14550</qgc_udp_port>
      <sdk_addr>INADDR_ANY</sdk_addr>
      <sdk_udp_port>14540</sdk_udp_port>
      <hil_mode>{{ hil_mode }}</hil_mode>
      <hil_state_level>false</hil_state_level>
      <enable_lockstep>true</enable_lockstep>
      <use_tcp>true</use_tcp>
      <motorSpeedCommandPubTopic>/gazebo/command/motor_speed</motorSpeedCommandPubTopic>
      <control_channels>
        <channel name="left_wheel_drive">
          <input_index>1</input_index>
          <input_offset>0</input_offset>
          <input_scaling>50</input_scaling>
          <zero_position_disarmed>0</zero_position_disarmed>
          <zero_position_armed>0</zero_position_armed>
          <joint_control_type>velocity</joint_control_type>
          <joint_name>left_wheel_joint</joint_name>
          <joint_control_pid>
            <p>40</p>
            <i>4</i>
            <d>0.4</d>
            <iMax>800</iMax>
            <iMin>-800</iMin>
            <cmdMax>1200</cmdMax>
            <cmdMin>-1200</cmdMin>
          </joint_control_pid>
        </channel>
        <channel name="right_wheel_drive">
          <input_index>0</input_index>
          <input_offset>0</input_offset>
          <input_scaling>50</input_scaling>
          <zero_position_disarmed>0</zero_position_disarmed>
          <zero_position_armed>0</zero_position_armed>
          <joint_control_type>velocity</joint_control_type>
          <joint_name>right_wheel_joint</joint_name>
          <joint_control_pid>
            <p>40</p>
            <i>4</i>
            <d>0.4</d>
            <iMax>800</iMax>
            <iMin>-800</iMin>
            <cmdMax>1200</cmdMax>
            <cmdMin>-1200</cmdMin>
          </joint_control_pid>
        </channel>
        <channel name="cutter_blades_drive">
          <input_index>2</input_index>
          <input_scaling>10</input_scaling>
          <joint_name>cutter_blades_joint</joint_name>
          <joint_control_pid>
            <p>40</p>
            <cmdMax>1200</cmdMax>
            <cmdMin>-1200</cmdMin>
          </joint_control_pid>
        </channel>
        <channel name="engine_visual_drive">
          <input_index>3</input_index>
          <input_scaling>10</input_scaling>
          <joint_name>engine_visual_joint</joint_name>
          <joint_control_pid>
            <p>40</p>
            <cmdMax>1200</cmdMax>
            <cmdMin>-1200</cmdMin>
          </joint_control_pid>
        </channel>
        <channel name="alarm_visual_drive">
          <input_index>4</input_index>
          <input_scaling>10</input_scaling>
          <joint_name>alarm_visual_joint</joint_name>
          <joint_control_pid>
            <p>40</p>
            <cmdMax>1200</cmdMax>
            <cmdMin>0</cmdMin>
          </joint_control_pid>
        </channel>
      </control_channels>
    </plugin>
  </model>
</sdf>
